<?xml version="1.0"?>
<robot xmlns:xacro="http://ros.org/wiki/xacro" name="two_wheeled_robot">
    
    <xacro:arg name="use_ros2_control" default="true"/>
    <xacro:arg name="sim_mode" default="true"/>

    <xacro:include filename="$(find two_wheeled_robot)/urdf/ros2_control2.xacro"/>   
	<!-- <xacro:include filename="$(find two_wheeled_robot)/urdf/gazebo_control.xacro"/>    -->
	<xacro:include filename="lidar2.xacro" />
    <xacro:include filename="camera2.xacro" />
    <link name="base_footprint"/>


	<joint name="base_joint" type="fixed">
		<parent link="base_footprint"/>
		<child link="base_link"/>
		<origin xyz="0 0 0" rpy="0 0 0" />
	</joint>
	<link name="base_link">
		<visual>
			<origin xyz="0 0 0.04" rpy="0 0 0"/>
			<geometry>
				<cylinder length="0.22" radius="0.3"/>
			</geometry>
			<material name="orange_base"/>
		</visual>
		<collision>
			<origin xyz="0 0 0.12" rpy="0 0 0"/>
			<geometry>
				<cylinder length="0.24" radius="0.3"/>
			</geometry>
		</collision>
		<inertial>
			<origin xyz="0 0 0" rpy="0 0 0"/>
			<mass value="30.0"/>
			<inertia ixx="0.819"  ixy="0"  ixz="0" iyy="0.819" iyz="0" izz="1.350" />
		</inertial>
	</link>


	<joint name="wheel_left_joint" type="continuous">
		<parent link="base_link"/>
		<child link="wheel_left_link"/>
		<origin xyz="0.0 0.23 0" rpy="-1.57 0 0"/>
		<axis xyz="0 0 1"/>
	</joint>
	<link name="wheel_left_link">
		<visual>
			<origin xyz="0 0 0" rpy="0 0 0"/>
			<geometry>
				<cylinder length="0.086" radius="0.13"/>
			</geometry>
			<material name="dark"/>
		</visual>
		<collision>
			<origin xyz="0 0 0" rpy="0 0 0"/>
			<geometry>
				<cylinder length="0.086" radius="0.13"/>
			</geometry>
		</collision>
		<inertial>
			<origin xyz="0 0 0" rpy="0 0 0"/>
			<mass value="0.1"/>
			<inertia ixx="0.001"  ixy="0"  ixz="0" iyy="0.001" iyz="0" izz="0.001" />
		</inertial>
	</link>


	<joint name="wheel_right_joint" type="continuous">
		<parent link="base_link"/>
		<child link="wheel_right_link"/>
		<origin xyz=" 0.0 -0.23 0" rpy="-1.57 0 0"/>
		<axis xyz="0 0 1"/>
	</joint>
	<link name="wheel_right_link">
		<visual>
			<origin xyz="0 0 0" rpy="0 0 0"/>
			<geometry>
				<cylinder length="0.086" radius="0.13"/>
			</geometry>
			<material name="dark"/>
		</visual>
		<collision>
			<origin xyz="0 0 0" rpy="0 0 0"/>
			<geometry>
				<cylinder length="0.086" radius="0.13"/>
			</geometry>
		</collision>
		<inertial>
			<origin xyz="0 0 0" rpy="0 0 0"/>
			<mass value="0.1"/>
			<inertia ixx="0.001"  ixy="0"  ixz="0" iyy="0.001" iyz="0" izz="0.001" />
		</inertial>
	</link>


	<joint name="caster_back_joint" type="continuous">
		<parent link="base_link"/>
		<child link="caster_back_link"/>
		<origin xyz="-0.235 0 -0.081" rpy="1.57 0 0"/>
		<axis xyz="0 0 1"/>
	</joint>
	<link name="caster_back_link">
		<visual>
			<origin xyz="0 0 0" rpy="0 0 0"/>
			<geometry>
				<cylinder length="0.026" radius="0.049"/>
			</geometry>
			<material name="black"/>
		</visual>
		<collision>
			<origin xyz="0 0 0" rpy="0 0 0"/>
			<geometry>
				<cylinder length="0.026" radius="0.049"/>
			</geometry>
		</collision>
		<inertial>
			<origin xyz="0 0 0" rpy="0 0 0"/>
			<mass value="0.1"/>
			<inertia ixx="0.001"  ixy="0"  ixz="0" iyy="0.001" iyz="0" izz="0.001" />
		</inertial>
	</link>


	<joint name="caster_front_joint" type="continuous">
		<parent link="base_link"/>
		<child link="caster_front_link"/>
		<origin xyz="0.235 0 -0.081" rpy="1.57 0 0"/>
		<axis xyz="0 0 1"/>
	</joint>
	<link name="caster_front_link">
		<visual>
			<origin xyz="0 0 0" rpy="0 0 0"/>
			<geometry>
				<cylinder length="0.026" radius="0.049"/>
			</geometry>
			<material name="black"/>
		</visual>
		<collision>
			<origin xyz="0 0 0" rpy="0 0 0"/>
			<geometry>
				<cylinder length="0.026" radius="0.049"/>
				<sphere radius="0.05"/>
			</geometry>
		</collision>
		<inertial>
			<origin xyz="0 0 0" rpy="0 0 0"/>
			<mass value="0.1"/>
			<inertia ixx="0.001"  ixy="0"  ixz="0" iyy="0.001" iyz="0" izz="0.001" />
		</inertial>
	</link>






	<joint name="3d_lisar_joint" type="fixed">
		<parent link="base_link"/>
		<child link="livox_frame"/>
		<!-- First location: top but reversed -->
		<origin xyz="0.045 -0.005 0.70" rpy="3.14 0 0"/>
		<!-- Second location: bottom but upright -->
		<!-- <origin xyz="0 0 0.27" rpy="0 0 0"/> -->
		<!-- Third location -->
		<!-- <origin xyz="0.250 0.0 0.510" rpy="3.14 0.49 0"/> -->
	</joint>
	<!-- <link name="livox/lidar"> -->
	<link name="livox_frame">
		<visual>
			<origin xyz="0 0 0" rpy="1.57 0 3.14"/>
			<geometry>				
				<mesh filename="$(find two_wheeled_robot)/meshes/sensors/mid-360-asm.dae" scale="1 1 1"/>
				<!-- <mesh filename="package://yellowbot_description/meshes/sensors/mid-360-fov-asm.stl" scale="0.001 0.001 0.001"/> -->
				<!-- <box size="0.065 0.065 0.060"/> -->
			</geometry>	
		</visual>
		<collision>
			<origin xyz="0 0 0" rpy="0 0 0"/>
			<geometry>
				<box size="0.065 0.065 0.060"/>
			</geometry>
		</collision>
		<inertial>
			<mass value="0.1" />
			<origin xyz="0 0 0" />
			<inertia ixx="0.001" ixy="0.0" ixz="0.0"
				iyy="0.001" iyz="0.0"
				izz="0.001" />
		</inertial>
	</link>


	<joint name="imu_joint" type="fixed">
		<parent link="livox_frame"/>
		<child link="imu_link"/>
		<origin xyz="0.011 0.023 -0.044" rpy="0 0 0"/>
	</joint>
	<link name="imu_link"/>



	<joint name="2d_lisar_joint" type="fixed">
		<parent link="base_link"/>
		<child link="laser"/>
		<origin xyz="0.27 -0.005 -0.005" rpy="0 0 -2.09"/>
	</joint>

	<link name="laser">
		<visual>
		<origin xyz="0 0 0.0" rpy="0 0 0"/>
		<geometry>
			<mesh filename="$(find two_wheeled_robot)/meshes/sensors/lds.stl" scale="0.001 0.001 0.001"/>
		</geometry>
		<material name="dark"/>
		</visual>

		<collision>
		<origin xyz="0.015 0 -0.0065" rpy="0 0 0"/>
		<geometry>
			<cylinder length="0.0315" radius="0.055"/>
		</geometry>
		</collision>

		<inertial>
		<mass value="0.114" />
		<origin xyz="0 0 0" />
		<inertia ixx="0.001" ixy="0.0" ixz="0.0"
				iyy="0.001" iyz="0.0"
				izz="0.001" />
		</inertial>
	</link>



	<joint name="camera_joint" type="fixed">
		<origin xyz="0.28 0 0.25" rpy="0 0 0"/>
		<parent link="base_link"/>
		<child link="camera_link"/>
	</joint>
	<link name="camera_link">
		<visual>
			<origin xyz="0 0 0" rpy="0 0 0"/>
			<geometry>
				<box size="0.015 0.030 0.027"/>
			</geometry>
			<material name="red"/>
		</visual>
		<collision>
			<origin xyz="0 0 0" rpy="0 0 0"/>
			<geometry>
				<box size="0.015 0.030 0.027"/>
			</geometry>
		</collision>
	</link>

















	<!-- Init colour in urdf/rviz-->
	<material name="black">
		<color rgba="0.0 0.0 0.0 1.0"/>
	</material>
	<material name="dark">
		<color rgba="0.3 0.3 0.3 1.0"/>
	</material>
	<material name="light_black">
		<color rgba="0.4 0.4 0.4 1.0"/>
	</material>
	<material name="blue">
		<color rgba="0.0 0.0 0.8 0.8"/>
	</material>
	<material name="green">
		<color rgba="0.0 0.8 0.0 1.0"/>
	</material>
	<material name="grey">
		<color rgba="0.5 0.5 0.5 1.0"/>
	</material>
	<material name="orange_base">
		<color rgba="${255/255} ${108/255} ${10/255} 1"/>
	</material>
	<material name="brown">
		<color rgba="${222/255} ${207/255} ${195/255} 1.0"/>
	</material>
	<material name="red">
		<color rgba="0.8 0.0 0.0 1.0"/>
	</material>
	<material name="white">
		<color rgba="1.0 1.0 1.0 1.0"/>
	</material>
</robot>
